<?xml version='1.0'?>

<robot name="my_robot" xmlns:xacro="http://www.ros.org/wiki/xacro">

  <!-- variables-->
  <xacro:property name="mass_wheel" value="0.50"/>
  <xacro:property name="length_wheel" value="0.05"/>
  <xacro:property name="radius_wheel" value="0.05"/>

  <!-- Macro for calculating inertia of cylindric wheel -->
  <xacro:macro name="wheel_inertia" params="m r h">
     <inertia ixx="${ m * ( 3 * r*r + h*h ) / 12}" ixy="0" ixz="0"
               iyy="${ m * ( 3 * r*r + h*h ) / 12}" iyz="0"
               izz="${ m * r / 2}" />
  </xacro:macro>

  <xacro:include filename="$(find my_robot)/urdf/my_robot.gazebo" />

  <link name="robot_footprint"></link>

  <joint name="robot_footprint_joint" type="fixed">
    <origin xyz="0 0 0" rpy="0 0 0" />
    <parent link="robot_footprint"/>
    <child link="chassis" />
  </joint>

  <link name='chassis'>
    <pose>0 0 0.05 0 0 0</pose>

    <inertial>
      <mass value="15.0"/>
      <origin xyz="0.0 0 0" rpy=" 0 0 0"/>
      <inertia
          ixx="0.1" ixy="0" ixz="0"
          iyy="0.1" iyz="0"
          izz="0.1"
      />
    </inertial>

    <collision name='collision'>
      <origin xyz="0 0 0" rpy=" 0 0 0"/> 
      <geometry>
        <box size=".4 .2 .05"/>
      </geometry>
    </collision>

    <visual name='chassis_visual'>
      <origin xyz="0 0 0" rpy=" 0 0 0"/>
      <geometry>
        <box size=".4 .2 .05"/>
      </geometry>
    </visual>

  </link>

  <link name="front_left_wheel">
    <inertial>
      <origin xyz="0 0 0" rpy="0 1.5707 1.5707"/>
      <mass value="${mass_wheel}"/>
      <wheel_inertia m="${mass_wheel}" r="${radius_wheel}" h="${length_wheel}" />
    </inertial>
    <collision>
      <origin xyz="0 0 0" rpy="0 1.5707 1.5707" />
      <geometry>
        <cylinder radius="${radius_wheel}" length="${length_wheel}" />
      </geometry>
    </collision>
    <visual>
      <origin xyz="0 0 0" rpy="0 1.5707 1.5707"/>
      <geometry>
        <cylinder length="${length_wheel}" radius="${radius_wheel}"/>
      </geometry>
    </visual>
  </link>

  <link name="back_left_wheel">
    <inertial>
      <origin xyz="0 0 0" rpy="0 1.5707 1.5707"/>
      <mass value="${mass_wheel}"/>
      <wheel_inertia m="${mass_wheel}" r="${radius_wheel}" h="${length_wheel}" />
    </inertial>
    <collision>
      <origin xyz="0 0 0" rpy="0 1.5707 1.5707" />
      <geometry>
        <cylinder radius="${radius_wheel}" length="${length_wheel}" />
      </geometry>
    </collision>
    <visual>
      <origin xyz="0 0 0" rpy="0 1.5707 1.5707"/>
      <geometry>
        <cylinder length="${length_wheel}" radius="${radius_wheel}"/>
      </geometry>
    </visual>
  </link>

  <link name="front_right_wheel">
    <inertial>
      <origin xyz="0 0 0" rpy=" 0 1.5707 1.5707"/>
      <mass value="${mass_wheel}"/>
      <wheel_inertia m="${mass_wheel}" r="${radius_wheel}" h="${length_wheel}" />
    </inertial>
    <collision>
      <origin xyz="0 0 0" rpy="0 1.5707 1.5707" />
      <geometry>
        <cylinder radius="${radius_wheel}" length="${length_wheel}" />
      </geometry>
    </collision>
    <visual>
      <origin xyz="0 0 0" rpy=" 0 1.5707 1.5707"/>
      <geometry>
        <cylinder length="${length_wheel}" radius="${radius_wheel}"/>
      </geometry>
    </visual>
  </link>

  <link name="back_right_wheel">
    <inertial>
      <origin xyz="0 0 0" rpy=" 0 1.5707 1.5707"/>
      <mass value="${mass_wheel}"/>
      <wheel_inertia m="${mass_wheel}" r="${radius_wheel}" h="${length_wheel}" />
    </inertial>
    <collision>
      <origin xyz="0 0 0" rpy="0 1.5707 1.5707" />
      <geometry>
        <cylinder radius="${radius_wheel}" length="${length_wheel}" />
      </geometry>
    </collision>
    <visual>
      <origin xyz="0 0 0" rpy=" 0 1.5707 1.5707"/>
      <geometry>
        <cylinder length="${length_wheel}" radius="${radius_wheel}"/>
      </geometry>
    </visual>
  </link>

  <link name="camera">
    <inertial>
      <origin xyz="0 0 0" rpy=" 0 0 0"/>
      <mass value="0.1"/>
      <inertia
          ixx="1e-6" ixy="0" ixz="0"
          iyy="1e-6" iyz="0"
          izz="1e-6"
      />
    </inertial>
    <collision>
      <origin xyz="0 0 0" rpy="0 0 0" />
      <geometry>
        <box size=".05 .05 .025"/>
      </geometry>
    </collision>
    <visual>
      <origin xyz="0 0 0" rpy=" 0 0 0"/>
      <geometry>
        <box size=".05 .05 .025"/>
      </geometry>
    </visual>
  </link>

  <link name="hokuyo">
    <inertial>
      <origin xyz="0 0 0" rpy=" 0 0 0"/>
      <mass value="1e-5"/>
      <inertia
          ixx="1e-6" ixy="0" ixz="0"
          iyy="1e-6" iyz="0"
          izz="1e-6"
      />
    </inertial>
    <collision>
      <origin xyz="0 0 0" rpy="0 0 0" />
      <geometry>
        <box size="0.1 0.1 0.1"/>
      </geometry>
    </collision>
    <visual>
      <origin xyz="0 0 0" rpy=" 0 0 0"/>
      <geometry>
        <mesh filename="package://my_robot/meshes/hokuyo.dae"/>
      </geometry>
    </visual>
  </link>

  <joint name="front_left_wheel_joint" type="continuous">
    <origin xyz="0.15 0.15 0" rpy="0 0 0"/>
    <parent link="chassis"/>
    <child link="front_left_wheel"/>
    <axis xyz="0 1 0" rpy="0 0 0"/>
    <dynamics damping="1.0" friction="1.0"/>
    <limit effort="10000" velocity="1000"/>
    <type>transmission_interface/SimpleTransmission</type>
  </joint>

  <joint name="back_left_wheel_joint" type="continuous">
    <origin xyz="-0.15 0.15 0" rpy="0 0 0"/>
    <parent link="chassis"/>
    <child link="back_left_wheel"/>
    <axis xyz="0 1 0" rpy="0 0 0"/>
    <dynamics damping="1.0" friction="1.0"/>
    <limit effort="10000" velocity="1000"/>
    <type>transmission_interface/SimpleTransmission</type>
  </joint>

  <joint name="front_right_wheel_joint" type="continuous">
    <origin xyz="0.15 -0.15 0" rpy="0 0 0"/>
    <parent link="chassis"/>
    <child link="front_right_wheel"/>
    <axis xyz="0 1 0" rpy="0 0 0"/>
    <dynamics damping="1.0" friction="1.0"/>
    <limit effort="10000" velocity="1000"/>
    <type>transmission_interface/SimpleTransmission</type>
  </joint>

  <joint name="back_right_wheel_joint" type="continuous">
    <origin xyz="-0.15 -0.15 0" rpy="0 0 0"/>
    <parent link="chassis"/>
    <child link="back_right_wheel"/>
    <axis xyz="0 1 0" rpy="0 0 0"/>
    <dynamics damping="1.0" friction="1.0"/>
    <limit effort="10000" velocity="1000"/>
    <type>transmission_interface/SimpleTransmission</type>
  </joint>

  <joint name="camera_joint" type="fixed">
    <origin xyz="0.2 0 0" rpy="0 0 0"/>
    <parent link="chassis"/>
    <child link="camera"/>
    <axis xyz="0 1 0" rpy="0 0 0"/>
  </joint>

  <joint name="hokuyo_joint" type="fixed">
    <origin xyz="0.15 0 0.05" rpy="0 0 0"/>
    <parent link="chassis"/>
    <child link="hokuyo"/>
    <axis xyz="0 1 0" rpy="0 0 0"/>
  </joint>

  <gazebo reference="chassis">
    <material>Gazebo/Blue</material>
  </gazebo>

  <gazebo reference="front_left_wheel">
    <material>Gazebo/Black</material>
    <!-- kp and kd for rubber -->
    <kp>1000000.0</kp>
    <kd>100.0</kd>
    <mu1>1.0</mu1>
    <mu2>1.0</mu2>
    <maxVel>1.0</maxVel>
    <minDepth>0.00</minDepth>
  </gazebo>

  <gazebo reference="back_left_wheel">
    <material>Gazebo/Black</material>
    <!-- kp and kd for rubber -->
    <kp>1000000.0</kp>
    <kd>100.0</kd>
    <mu1>1.0</mu1>
    <mu2>1.0</mu2>
    <maxVel>1.0</maxVel>
    <minDepth>0.00</minDepth>
  </gazebo>

  <gazebo reference="front_right_wheel">
    <material>Gazebo/Black</material>
    <!-- kp and kd for rubber -->
    <kp>1000000.0</kp>
    <kd>100.0</kd>
    <mu1>1.0</mu1>
    <mu2>1.0</mu2>
    <maxVel>1.0</maxVel>
    <minDepth>0.00</minDepth>
  </gazebo>

  <gazebo reference="back_right_wheel">
    <material>Gazebo/Black</material>
    <!-- kp and kd for rubber -->
    <kp>1000000.0</kp>
    <kd>100.0</kd>
    <mu1>1.0</mu1>
    <mu2>1.0</mu2>
    <maxVel>1.0</maxVel>
    <minDepth>0.00</minDepth>
  </gazebo>

  <gazebo reference="camera">
    <material>Gazebo/Red</material>
  </gazebo>

  <transmission name="front_left_wheel_joint_trans" >
   <type>transmission_interface/SimpleTransmission</type>
   <joint name="front_left_wheel_joint">
     <hardwareInterface>hardware_interface/EffortJointInterface</hardwareInterface>
   </joint>
   <actuator name="front_left_wheel_joint_motor">
     <hardwareInterface>hardware_interface/EffortJointInterface</hardwareInterface>
     <mechanicalReduction>1</mechanicalReduction>
   </actuator>
  </transmission>

  <transmission name="back_left_wheel_joint_trans" >
   <type>transmission_interface/SimpleTransmission</type>
   <joint name="back_left_wheel_joint">
     <hardwareInterface>hardware_interface/EffortJointInterface</hardwareInterface>
   </joint>
   <actuator name="back_left_wheel_joint_motor">
     <hardwareInterface>hardware_interface/EffortJointInterface</hardwareInterface>
     <mechanicalReduction>1</mechanicalReduction>
   </actuator>
  </transmission>

  <transmission name="front_right_wheel_joint_trans" >
   <type>transmission_interface/SimpleTransmission</type>
   <joint name="front_right_wheel_joint">
     <hardwareInterface>hardware_interface/EffortJointInterface</hardwareInterface>
   </joint>
   <actuator name="front_right_wheel_joint_motor">
     <hardwareInterface>hardware_interface/EffortJointInterface</hardwareInterface>
     <mechanicalReduction>1</mechanicalReduction>
   </actuator>
  </transmission>

  <transmission name="back_right_wheel_joint_trans" >
   <type>transmission_interface/SimpleTransmission</type>
   <joint name="back_right_wheel_joint">
     <hardwareInterface>hardware_interface/EffortJointInterface</hardwareInterface>
   </joint>
   <actuator name="back_right_wheel_joint_motor">
     <hardwareInterface>hardware_interface/EffortJointInterface</hardwareInterface>
     <mechanicalReduction>1</mechanicalReduction>
   </actuator>
  </transmission>

</robot>
